<?xml version="1.0" encoding="utf-8"?>
<!-- This URDF was automatically created by SolidWorks to URDF Exporter! Originally created by Stephen Brawner (brawner@gmail.com) 
     Commit Version: 1.6.0-4-g7f85cfe  Build Version: 1.6.7995.38578
     For more information, please see http://wiki.ros.org/sw_urdf_exporter -->
<robot
  name="one_leg">
  <link
    name="base_link">
    <inertial>
      <origin
        xyz="7.21644966006352E-16 -0.63286005182812 0.020052425270642"
        rpy="0 0 0" />
      <mass
        value="0.00526659250823866" />
      <inertia
        ixx="1.57167590827307E-06"
        ixy="6.98764716172858E-23"
        ixz="1.03549426819276E-22"
        iyy="1.66436600986042E-06"
        iyz="1.37354397942886E-07"
        izz="1.77521685073794E-06" />
    </inertial>
    <visual>
      <origin
        xyz="0 0 0"
        rpy="0 0 0" />
      <geometry>
        <mesh
          filename="package://one_leg/meshes/base_link.STL" />
      </geometry>
      <material
        name="">
        <color
          rgba="0.792156862745098 0.819607843137255 0.933333333333333 1" />
      </material>
    </visual>
    <collision>
      <origin
        xyz="0 0 0"
        rpy="0 0 0" />
      <geometry>
        <mesh
          filename="package://one_leg/meshes/base_link.STL" />
      </geometry>
    </collision>
  </link>
  <link
    name="tube_lower">
    <inertial>
      <origin
        xyz="-1.4622E-08 -0.0051305 -0.0075999"
        rpy="0 0 0" />
      <mass
        value="0.18507" />
      <inertia
        ixx="0.029708"
        ixy="1.9233E-09"
        ixz="-3.379E-10"
        iyy="0.020424"
        iyz="-0.013757"
        izz="0.0093211" />
    </inertial>
    <visual>
      <origin
        xyz="0 0 0"
        rpy="0 0 0" />
      <geometry>
        <mesh
          filename="package://one_leg/meshes/tube_lower.STL" />
      </geometry>
      <material
        name="">
        <color
          rgba="0.79216 0.81961 0.93333 1" />
      </material>
    </visual>
    <collision>
      <origin
        xyz="0 0 0"
        rpy="0 0 0" />
      <geometry>
        <mesh
          filename="package://one_leg/meshes/tube_lower.STL" />
      </geometry>
    </collision>
  </link>
  <joint
    name="tube_lower_j"
    type="fixed">
    <origin
      xyz="0 -0.23476 0.60998"
      rpy="0 0 0" />
    <parent
      link="base_link" />
    <child
      link="tube_lower" />
    <axis
      xyz="0 0 0" />
  </joint>
  <link
    name="bracket_LL">
    <inertial>
      <origin
        xyz="2.7756E-17 0.0082456 -0.028397"
        rpy="0 0 0" />
      <mass
        value="0.013935" />
      <inertia
        ixx="5.5018E-06"
        ixy="1.7825E-22"
        ixz="1.3611E-21"
        iyy="5.4749E-06"
        iyz="-4.727E-07"
        izz="3.2426E-06" />
    </inertial>
    <visual>
      <origin
        xyz="0 0 0"
        rpy="0 0 0" />
      <geometry>
        <mesh
          filename="package://one_leg/meshes/bracket_LL.STL" />
      </geometry>
      <material
        name="">
        <color
          rgba="0.74902 0.74902 0.74902 1" />
      </material>
    </visual>
    <collision>
      <origin
        xyz="0 0 0"
        rpy="0 0 0" />
      <geometry>
        <mesh
          filename="package://one_leg/meshes/bracket_LL.STL" />
      </geometry>
    </collision>
  </link>
  <joint
    name="bracket_LL_j"
    type="fixed">
    <origin
      xyz="0 0.20396 0.39752"
      rpy="0 0 0" />
    <parent
      link="tube_lower" />
    <child
      link="bracket_LL" />
    <axis
      xyz="0 0 0" />
  </joint>
  <link
    name="lin_lower_rod">
    <inertial>
      <origin
        xyz="4.7776E-08 6.4425E-05 0.00084681"
        rpy="0 0 0" />
      <mass
        value="0.084578" />
      <inertia
        ixx="0.00051388"
        ixy="1.0836E-11"
        ixz="-6.8794E-13"
        iyy="0.00051093"
        iyz="-3.8547E-05"
        izz="7.1698E-06" />
    </inertial>
    <visual>
      <origin
        xyz="0 0 0"
        rpy="0 0 0" />
      <geometry>
        <mesh
          filename="package://one_leg/meshes/lin_lower_rod.STL" />
      </geometry>
      <material
        name="">
        <color
          rgba="0.89412 0.91373 0.92941 1" />
      </material>
    </visual>
    <collision>
      <origin
        xyz="0 0 0"
        rpy="0 0 0" />
      <geometry>
        <mesh
          filename="package://one_leg/meshes/lin_lower_rod.STL" />
      </geometry>
    </collision>
  </link>
  <joint
    name="lin_lower_rod_j"
    type="revolute">
    <origin
      xyz="0 0.0097475 0.12813"
      rpy="0 0 0" />
    <parent
      link="bracket_LL" />
    <child
      link="lin_lower_rod" />
    <axis
      xyz="-1 0 0" />
    <limit
      lower="0.349"
      upper="-0.349"
      effort="10"
      velocity="2" />
  </joint>
  <link
    name="lin_lower_body">
    <inertial>
      <origin
        xyz="8.3267E-17 0.0065636 0.20895"
        rpy="0 0 0" />
      <mass
        value="0.30902" />
      <inertia
        ixx="0.0036475"
        ixy="1.0882E-20"
        ixz="-1.5673E-18"
        iyy="0.0035658"
        iyz="8.1104E-05"
        izz="0.00013212" />
    </inertial>
    <visual>
      <origin
        xyz="0 0 0"
        rpy="0 0 0" />
      <geometry>
        <mesh
          filename="package://one_leg/meshes/lin_lower_body.STL" />
      </geometry>
      <material
        name="">
        <color
          rgba="0.79216 0.81961 0.93333 1" />
      </material>
    </visual>
    <collision>
      <origin
        xyz="0 0 0"
        rpy="0 0 0" />
      <geometry>
        <mesh
          filename="package://one_leg/meshes/lin_lower_body.STL" />
      </geometry>
    </collision>
  </link>
  <joint
    name="lin_lower_body_j"
    type="prismatic">
    <origin
      xyz="0 0 0"
      rpy="0 0 0" />
    <parent
      link="lin_lower_rod" />
    <child
      link="lin_lower_body" />
    <axis
      xyz="0 0.075815 0.99712" />
    <limit
      lower="0.09"
      upper="-0.09"
      effort="1600"
      velocity="0.005" />
  </joint>
  <link
    name="bracket_LU">
    <inertial>
      <origin
        xyz="-8.32667268468867E-17 0.0145342780983798 0.0256538633585249"
        rpy="0 0 0" />
      <mass
        value="0.0137645141673134" />
      <inertia
        ixx="5.48133005963742E-06"
        ixy="1.45349255649419E-20"
        ixz="2.35230261669865E-21"
        iyy="5.57839537963951E-06"
        iyz="-8.71254324255324E-08"
        izz="3.11700050501289E-06" />
    </inertial>
    <visual>
      <origin
        xyz="0 0 0"
        rpy="0 0 0" />
      <geometry>
        <mesh
          filename="package://one_leg/meshes/bracket_LU.STL" />
      </geometry>
      <material
        name="">
        <color
          rgba="0.749019607843137 0.749019607843137 0.749019607843137 1" />
      </material>
    </visual>
    <collision>
      <origin
        xyz="0 0 0"
        rpy="0 0 0" />
      <geometry>
        <mesh
          filename="package://one_leg/meshes/bracket_LU.STL" />
      </geometry>
    </collision>
  </link>
  <joint
    name="bracket_LU_j"
    type="revolute">
    <origin
      xyz="0 0.025528 0.33557"
      rpy="0 0 0" />
    <parent
      link="lin_lower_body" />
    <child
      link="bracket_LU" />
    <axis
      xyz="1 0 0" />
    <limit
      lower="0.349"
      upper="-0.349"
      effort="10"
      velocity="2" />
  </joint>
  <link
    name="tube_upper_B">
    <inertial>
      <origin
        xyz="1.3931E-08 -0.00064262 0.0017303"
        rpy="0 0 0" />
      <mass
        value="0.18277" />
      <inertia
        ixx="0.028804"
        ixy="1.0256E-10"
        ixz="9.5576E-10"
        iyy="0.025316"
        iyz="0.0093895"
        izz="0.0035249" />
    </inertial>
    <visual>
      <origin
        xyz="0 0 0"
        rpy="0 0 0" />
      <geometry>
        <mesh
          filename="package://one_leg/meshes/tube_upper_B.STL" />
      </geometry>
      <material
        name="">
        <color
          rgba="0.79216 0.81961 0.93333 1" />
      </material>
    </visual>
    <collision>
      <origin
        xyz="0 0 0"
        rpy="0 0 0" />
      <geometry>
        <mesh
          filename="package://one_leg/meshes/tube_upper_B.STL" />
      </geometry>
    </collision>
  </link>
  <joint
    name="tube_upper_B_j"
    type="fixed">
    <origin
      xyz="0 -0.089245 0.39334"
      rpy="0 0 0" />
    <parent
      link="bracket_LU" />
    <child
      link="tube_upper_B" />
    <axis
      xyz="0 0 0" />
  </joint>
  <link
    name="leg_lower">
    <inertial>
      <origin
        xyz="-0.0004576 -0.018915 0.0022849"
        rpy="0 0 0" />
      <mass
        value="0.027338" />
      <inertia
        ixx="4.928E-05"
        ixy="-7.5523E-08"
        ixz="-1.3947E-07"
        iyy="4.3901E-05"
        iyz="-5.7619E-06"
        izz="1.5115E-05" />
    </inertial>
    <visual>
      <origin
        xyz="0 0 0"
        rpy="0 0 0" />
      <geometry>
        <mesh
          filename="package://one_leg/meshes/leg_lower.STL" />
      </geometry>
      <material
        name="">
        <color
          rgba="0.79216 0.81961 0.93333 1" />
      </material>
    </visual>
    <collision>
      <origin
        xyz="0 0 0"
        rpy="0 0 0" />
      <geometry>
        <mesh
          filename="package://one_leg/meshes/leg_lower.STL" />
      </geometry>
    </collision>
  </link>
  <joint
    name="leg_lower_j"
    type="revolute">
    <origin
      xyz="0.00059077 0.39035 0.58958"
      rpy="0 0 0" />
    <parent
      link="tube_lower" />
    <child
      link="leg_lower" />
    <axis
      xyz="-1 0 0" />
    <limit
      lower="0.349"
      upper="-0.349"
      effort="100"
      velocity="2" />
  </joint>
  <link
    name="tube_upper">
    <inertial>
      <origin
        xyz="1.3931E-08 -0.00064262 0.0017303"
        rpy="0 0 0" />
      <mass
        value="0.18277" />
      <inertia
        ixx="0.028804"
        ixy="1.0256E-10"
        ixz="9.5576E-10"
        iyy="0.025316"
        iyz="0.0093895"
        izz="0.0035249" />
    </inertial>
    <visual>
      <origin
        xyz="0 0 0"
        rpy="0 0 0" />
      <geometry>
        <mesh
          filename="package://one_leg/meshes/tube_upper.STL" />
      </geometry>
      <material
        name="">
        <color
          rgba="0.79216 0.81961 0.93333 1" />
      </material>
    </visual>
    <collision>
      <origin
        xyz="0 0 0"
        rpy="0 0 0" />
      <geometry>
        <mesh
          filename="package://one_leg/meshes/tube_upper.STL" />
      </geometry>
    </collision>
  </link>
  <joint
    name="tube_upper_j"
    type="fixed">
    <origin
      xyz="-0.00058975 -0.24036 0.66498"
      rpy="0 0 0" />
    <parent
      link="leg_lower" />
    <child
      link="tube_upper" />
    <axis
      xyz="0 0 0" />
  </joint>
  <link
    name="bracket_UL">
    <inertial>
      <origin
        xyz="-1.4155E-15 0.027917 -0.0098557"
        rpy="0 0 0" />
      <mass
        value="0.013955" />
      <inertia
        ixx="5.5162E-06"
        ixy="-4.1198E-22"
        ixz="-2.5902E-22"
        iyy="4.4531E-06"
        iyz="1.216E-06"
        izz="4.2791E-06" />
    </inertial>
    <visual>
      <origin
        xyz="0 0 0"
        rpy="0 0 0" />
      <geometry>
        <mesh
          filename="package://one_leg/meshes/bracket_UL.STL" />
      </geometry>
      <material
        name="">
        <color
          rgba="0.74902 0.74902 0.74902 1" />
      </material>
    </visual>
    <collision>
      <origin
        xyz="0 0 0"
        rpy="0 0 0" />
      <geometry>
        <mesh
          filename="package://one_leg/meshes/bracket_UL.STL" />
      </geometry>
    </collision>
  </link>
  <joint
    name="bracket_UL_J"
    type="fixed">
    <origin
      xyz="0 -0.16636 0.2948"
      rpy="0 0 0" />
    <parent
      link="tube_upper" />
    <child
      link="bracket_UL" />
    <axis
      xyz="0 0 0" />
  </joint>
  <link
    name="lin_upper_rod">
    <inertial>
      <origin
        xyz="-4.7776E-08 -0.00064279 0.00055503"
        rpy="0 0 0" />
      <mass
        value="0.084578" />
      <inertia
        ixx="0.00051388"
        ixy="7.1986E-12"
        ixz="8.1286E-12"
        iyy="0.00022191"
        iyz="0.00025209"
        izz="0.00029619" />
    </inertial>
    <visual>
      <origin
        xyz="0 0 0"
        rpy="0 0 0" />
      <geometry>
        <mesh
          filename="package://one_leg/meshes/lin_upper_rod.STL" />
      </geometry>
      <material
        name="">
        <color
          rgba="0.89412 0.91373 0.92941 1" />
      </material>
    </visual>
    <collision>
      <origin
        xyz="0 0 0"
        rpy="0 0 0" />
      <geometry>
        <mesh
          filename="package://one_leg/meshes/lin_upper_rod.STL" />
      </geometry>
    </collision>
  </link>
  <joint
    name="lin_upper_rod_j"
    type="revolute">
    <origin
      xyz="0 -0.09726 0.083981"
      rpy="0 0 0" />
    <parent
      link="bracket_UL" />
    <child
      link="lin_upper_rod" />
    <axis
      xyz="1 0 0" />
    <limit
      lower="0.349"
      upper="-0.349"
      effort="10"
      velocity="2" />
  </joint>
  <link
    name="lin_upper_body">
    <inertial>
      <origin
        xyz="4.996E-16 -0.19934 0.15983"
        rpy="0 0 0" />
      <mass
        value="0.30902" />
      <inertia
        ixx="0.0036475"
        ixy="-2.5461E-19"
        ixz="1.9211E-19"
        iyy="0.0012672"
        iyz="0.0016173"
        izz="0.0024308" />
    </inertial>
    <visual>
      <origin
        xyz="0 0 0"
        rpy="0 0 0" />
      <geometry>
        <mesh
          filename="package://one_leg/meshes/lin_upper_body.STL" />
      </geometry>
      <material
        name="">
        <color
          rgba="0.79216 0.81961 0.93333 1" />
      </material>
    </visual>
    <collision>
      <origin
        xyz="0 0 0"
        rpy="0 0 0" />
      <geometry>
        <mesh
          filename="package://one_leg/meshes/lin_upper_body.STL" />
      </geometry>
    </collision>
  </link>
  <joint
    name="lin_upper_body_j"
    type="prismatic">
    <origin
      xyz="0 0 0"
      rpy="0 0 0" />
    <parent
      link="lin_upper_rod" />
    <child
      link="lin_upper_body" />
    <axis
      xyz="0 -0.75688 0.65355" />
    <limit
      lower="0.09"
      upper="0.09"
      effort="1600"
      velocity="0.005" />
  </joint>
  <link
    name="bracket_UU">
    <inertial>
      <origin
        xyz="0 -0.0189596464258239 0.0227384747054926"
        rpy="0 0 0" />
      <mass
        value="0.013955365921019" />
      <inertia
        ixx="5.51624030349116E-06"
        ixy="-3.83973881484102E-22"
        ixz="7.82576461875349E-22"
        iyy="3.50642300774646E-06"
        iyz="8.64313890009256E-07"
        izz="5.22581549476594E-06" />
    </inertial>
    <visual>
      <origin
        xyz="0 0 0"
        rpy="0 0 0" />
      <geometry>
        <mesh
          filename="package://one_leg/meshes/bracket_UU.STL" />
      </geometry>
      <material
        name="">
        <color
          rgba="0.749019607843137 0.749019607843137 0.749019607843137 1" />
      </material>
    </visual>
    <collision>
      <origin
        xyz="0 0 0"
        rpy="0 0 0" />
      <geometry>
        <mesh
          filename="package://one_leg/meshes/bracket_UU.STL" />
      </geometry>
    </collision>
  </link>
  <joint
    name="bracket_UU_J"
    type="revolute">
    <origin
      xyz="0 -0.2899 0.25033"
      rpy="0 0 0" />
    <parent
      link="lin_upper_body" />
    <child
      link="bracket_UU" />
    <axis
      xyz="-1 0 0" />
    <limit
      lower="0.349"
      upper="-0.349"
      effort="10"
      velocity="2" />
  </joint>
  <link
    name="chassis_B">
    <inertial>
      <origin
        xyz="4.41137195178465E-06 0.000918359101978572 2.60202222651107E-05"
        rpy="0 0 0" />
      <mass
        value="0.6643231691487" />
      <inertia
        ixx="0.124497537684338"
        ixy="1.03440379129647E-07"
        ixz="3.29978112881104E-09"
        iyy="0.000272415804836354"
        iyz="1.06181136709903E-05"
        izz="0.124497811349338" />
    </inertial>
    <visual>
      <origin
        xyz="0 0 0"
        rpy="0 0 0" />
      <geometry>
        <mesh
          filename="package://one_leg/meshes/chassis_B.STL" />
      </geometry>
      <material
        name="">
        <color
          rgba="0.792156862745098 0.819607843137255 0.933333333333333 1" />
      </material>
    </visual>
    <collision>
      <origin
        xyz="0 0 0"
        rpy="0 0 0" />
      <geometry>
        <mesh
          filename="package://one_leg/meshes/chassis_B.STL" />
      </geometry>
    </collision>
  </link>
  <joint
    name="chassis__B_j"
    type="fixed">
    <origin
      xyz="0 0.6383 0.05635"
      rpy="0 0 0" />
    <parent
      link="bracket_UU" />
    <child
      link="chassis_B" />
    <axis
      xyz="0 0 0" />
  </joint>
  <link
    name="leg_upper">
    <inertial>
      <origin
        xyz="-0.00045795 -0.014191 -0.020409"
        rpy="0 0 0" />
      <mass
        value="0.027364" />
      <inertia
        ixx="4.9286E-05"
        ixy="6.9439E-08"
        ixz="-1.4126E-07"
        iyy="2.8634E-05"
        iyz="1.011E-05"
        izz="3.0388E-05" />
    </inertial>
    <visual>
      <origin
        xyz="0 0 0"
        rpy="0 0 0" />
      <geometry>
        <mesh
          filename="package://one_leg/meshes/leg_upper.STL" />
      </geometry>
      <material
        name="">
        <color
          rgba="0.79216 0.81961 0.93333 1" />
      </material>
    </visual>
    <collision>
      <origin
        xyz="0 0 0"
        rpy="0 0 0" />
      <geometry>
        <mesh
          filename="package://one_leg/meshes/leg_upper.STL" />
      </geometry>
    </collision>
  </link>
  <joint
    name="leg_upper_j"
    type="revolute">
    <origin
      xyz="0.00059009 -0.25204 0.66064"
      rpy="0 0 0" />
    <parent
      link="tube_upper" />
    <child
      link="leg_upper" />
    <axis
      xyz="1 0 0" />
    <limit
      lower="0.349"
      upper="-0.349"
      effort="100"
      velocity="2" />
  </joint>
  <link
    name="chassis">
    <inertial>
      <origin
        xyz="4.4114E-06 0.00091836 2.602E-05"
        rpy="0 0 0" />
      <mass
        value="0.66432" />
      <inertia
        ixx="0.1245"
        ixy="1.0344E-07"
        ixz="3.2998E-09"
        iyy="0.00027242"
        iyz="1.0618E-05"
        izz="0.1245" />
    </inertial>
    <visual>
      <origin
        xyz="0 0 0"
        rpy="0 0 0" />
      <geometry>
        <mesh
          filename="package://one_leg/meshes/chassis.STL" />
      </geometry>
      <material
        name="">
        <color
          rgba="0.79216 0.81961 0.93333 1" />
      </material>
    </visual>
    <collision>
      <origin
        xyz="0 0 0"
        rpy="0 0 0" />
      <geometry>
        <mesh
          filename="package://one_leg/meshes/chassis.STL" />
      </geometry>
    </collision>
  </link>
  <joint
    name="chassis_j"
    type="fixed">
    <origin
      xyz="-0.00059112 0.33681 0.024819"
      rpy="0 0 0" />
    <parent
      link="leg_upper" />
    <child
      link="chassis" />
    <axis
      xyz="0 0 0" />
  </joint>
</robot>